 * Debug mode: off
[31m[1mWARNING: This is a development server. Do not use it in a production deployment. Use a production WSGI server instead.[0m
 * Running on all addresses (0.0.0.0)
 * Running on http://127.0.0.1:5000
 * Running on http://10.244.3.3:5000
[33mPress CTRL+C to quit[0m
172.22.0.2 - - [18/Jun/2023 04:37:38] "[33mGET / HTTP/1.1[0m" 404 -
172.22.0.2 - - [18/Jun/2023 04:37:38] "[33mGET /favicon.ico HTTP/1.1[0m" 404 -
10.244.3.1 - - [18/Jun/2023 04:37:42] "[33mGET / HTTP/1.1[0m" 404 -
10.244.3.1 - - [18/Jun/2023 04:37:42] "[33mGET /favicon.ico HTTP/1.1[0m" 404 -
[2023-06-18 04:37:58,684] ERROR in app: Exception on /api/attendees [GET]
Traceback (most recent call last):
  File "/usr/local/lib/python3.9/site-packages/flask/app.py", line 2190, in wsgi_app
    response = self.full_dispatch_request()
  File "/usr/local/lib/python3.9/site-packages/flask/app.py", line 1486, in full_dispatch_request
    rv = self.handle_user_exception(e)
  File "/usr/local/lib/python3.9/site-packages/flask/app.py", line 1484, in full_dispatch_request
    rv = self.dispatch_request()
  File "/usr/local/lib/python3.9/site-packages/flask/app.py", line 1469, in dispatch_request
    return self.ensure_sync(self.view_functions[rule.endpoint])(**view_args)
  File "/app/app.py", line 16, in getpost
    for i in db.find():
  File "/usr/local/lib/python3.9/site-packages/pymongo/cursor.py", line 1248, in next
    if len(self.__data) or self._refresh():
  File "/usr/local/lib/python3.9/site-packages/pymongo/cursor.py", line 1139, in _refresh
    self.__session = self.__collection.database.client._ensure_session()
  File "/usr/local/lib/python3.9/site-packages/pymongo/mongo_client.py", line 1740, in _ensure_session
    return self.__start_session(True, causal_consistency=False)
  File "/usr/local/lib/python3.9/site-packages/pymongo/mongo_client.py", line 1685, in __start_session
    self._topology._check_implicit_session_support()
  File "/usr/local/lib/python3.9/site-packages/pymongo/topology.py", line 538, in _check_implicit_session_support
    self._check_session_support()
  File "/usr/local/lib/python3.9/site-packages/pymongo/topology.py", line 554, in _check_session_support
    self._select_servers_loop(
  File "/usr/local/lib/python3.9/site-packages/pymongo/topology.py", line 238, in _select_servers_loop
    raise ServerSelectionTimeoutError(
pymongo.errors.ServerSelectionTimeoutError: db:27017: [Errno 111] Connection refused, Timeout: 30s, Topology Description: <TopologyDescription id: 648e889e619f96a4fb8d6397, topology_type: Unknown, servers: [<ServerDescription ('db', 27017) server_type: Unknown, rtt: None, error=AutoReconnect('db:27017: [Errno 111] Connection refused')>]>
10.244.1.4 - - [18/Jun/2023 04:37:58] "[35m[1mGET /api/attendees HTTP/1.0[0m" 500 -
10.244.3.1 - - [18/Jun/2023 04:39:00] "[33mGET / HTTP/1.1[0m" 404 -
10.244.3.1 - - [18/Jun/2023 04:41:04] "[33mGET / HTTP/1.1[0m" 404 -
172.22.0.5 - - [18/Jun/2023 04:41:08] "[33mGET / HTTP/1.1[0m" 404 -
172.22.0.5 - - [18/Jun/2023 04:41:09] "[33mGET /favicon.ico HTTP/1.1[0m" 404 -
10.244.3.1 - - [18/Jun/2023 04:41:27] "[33mGET / HTTP/1.1[0m" 404 -
[2023-06-18 04:42:08,689] ERROR in app: Exception on /api/attendees [GET]
Traceback (most recent call last):
  File "/usr/local/lib/python3.9/site-packages/flask/app.py", line 2190, in wsgi_app
    response = self.full_dispatch_request()
  File "/usr/local/lib/python3.9/site-packages/flask/app.py", line 1486, in full_dispatch_request
    rv = self.handle_user_exception(e)
  File "/usr/local/lib/python3.9/site-packages/flask/app.py", line 1484, in full_dispatch_request
    rv = self.dispatch_request()
  File "/usr/local/lib/python3.9/site-packages/flask/app.py", line 1469, in dispatch_request
    return self.ensure_sync(self.view_functions[rule.endpoint])(**view_args)
  File "/app/app.py", line 16, in getpost
    for i in db.find():
  File "/usr/local/lib/python3.9/site-packages/pymongo/cursor.py", line 1248, in next
    if len(self.__data) or self._refresh():
  File "/usr/local/lib/python3.9/site-packages/pymongo/cursor.py", line 1139, in _refresh
    self.__session = self.__collection.database.client._ensure_session()
  File "/usr/local/lib/python3.9/site-packages/pymongo/mongo_client.py", line 1740, in _ensure_session
    return self.__start_session(True, causal_consistency=False)
  File "/usr/local/lib/python3.9/site-packages/pymongo/mongo_client.py", line 1685, in __start_session
    self._topology._check_implicit_session_support()
  File "/usr/local/lib/python3.9/site-packages/pymongo/topology.py", line 538, in _check_implicit_session_support
    self._check_session_support()
  File "/usr/local/lib/python3.9/site-packages/pymongo/topology.py", line 554, in _check_session_support
    self._select_servers_loop(
  File "/usr/local/lib/python3.9/site-packages/pymongo/topology.py", line 238, in _select_servers_loop
    raise ServerSelectionTimeoutError(
pymongo.errors.ServerSelectionTimeoutError: db:27017: [Errno 111] Connection refused, Timeout: 30s, Topology Description: <TopologyDescription id: 648e889e619f96a4fb8d6397, topology_type: Unknown, servers: [<ServerDescription ('db', 27017) server_type: Unknown, rtt: None, error=AutoReconnect('db:27017: [Errno 111] Connection refused')>]>
10.244.3.1 - - [18/Jun/2023 04:42:08] "[35m[1mGET /api/attendees HTTP/1.1[0m" 500 -
